2024-10-31 18:09:09.904 - INFO    - MainThread - client.py:204 [connectAsync] - Connecting to 127.0.0.1:7497 with clientId 27628...
2024-10-31 18:09:09.906 - INFO    - MainThread - client.py:212 [connectAsync] - Connected
2024-10-31 18:09:09.912 - INFO    - MainThread - client.py:341 [_onSocketHasData] - Logged on to server version 176
2024-10-31 18:09:09.919 - INFO    - MainThread - wrapper.py:1149 [error] - Warning 2104, reqId -1: Market data farm connection is OK:hfarm
2024-10-31 18:09:09.920 - INFO    - MainThread - wrapper.py:1149 [error] - Warning 2104, reqId -1: Market data farm connection is OK:cashfarm
2024-10-31 18:09:09.921 - INFO    - MainThread - wrapper.py:1149 [error] - Warning 2104, reqId -1: Market data farm connection is OK:usfarm.nj
2024-10-31 18:09:09.922 - INFO    - MainThread - wrapper.py:1149 [error] - Warning 2104, reqId -1: Market data farm connection is OK:usfarm
2024-10-31 18:09:09.922 - INFO    - MainThread - wrapper.py:1149 [error] - Warning 2106, reqId -1: HMDS data farm connection is OK:euhmds
2024-10-31 18:09:09.922 - INFO    - MainThread - wrapper.py:1149 [error] - Warning 2106, reqId -1: HMDS data farm connection is OK:apachmds
2024-10-31 18:09:09.923 - INFO    - MainThread - wrapper.py:1149 [error] - Warning 2106, reqId -1: HMDS data farm connection is OK:fundfarm
2024-10-31 18:09:09.923 - ERROR   - MainThread - decoder.py:189 [handler] - Error for managedAccounts:
Traceback (most recent call last):
  File "c:\Users\felin\AppData\Local\Programs\Python\Python313\Lib\site-packages\ib_insync\decoder.py", line 187, in handler
    method(*args)
    ~~~~~~^^^^^^^
  File "c:\Users\felin\AppData\Local\Programs\Python\Python313\Lib\site-packages\ib_insync\wrapper.py", line 241, in managedAccounts
    self.ib.managedAccounts(accountsList)
    ~~~~~~~~~~~~~~~~~~~~~~~^^^^^^^^^^^^^^
TypeError: IBStoreInsync.managedAccounts() takes 1 positional argument but 2 were given
2024-10-31 18:09:09.927 - INFO    - MainThread - client.py:218 [connectAsync] - API connection ready
2024-10-31 18:09:09.928 - INFO    - MainThread - wrapper.py:1149 [error] - Warning 2106, reqId -1: HMDS data farm connection is OK:ushmds
2024-10-31 18:09:09.929 - INFO    - MainThread - wrapper.py:1149 [error] - Warning 2158, reqId -1: Sec-def data farm connection is OK:secdefhk
2024-10-31 18:09:10.264 - INFO    - MainThread - ibstore_insync.py:2710 [connectAsync] - Synchronization complete
2024-10-31 18:09:59.465 - ERROR   - MainThread - decoder.py:200 [interpret] - Error handling fields: ['10', '3', 'EUR', 'CASH', '', '0', '', 'IDEALPRO', 'USD', 'EUR.USD', 'EUR.USD', 'EUR.USD', '12087792', '0.00005', '', 'ACTIVETIM,AD,ADJUST,ALERT,ALGO,ALLOC,AVGCOST,BASKET,CASHQTY,COND,CONDORDER,DAY,DEACT,DEACTDIS,DEACTEOD,GAT,GTC,GTD,GTT,HID,IOC,LIT,LMT,MIT,MKT,NONALGO,OCA,REL,RELPCTOFS,SCALE,SCALERST,STP,STPLMT,TRAIL,TRAILLIT,TRAILLMT,TRAILMIT,WHATIF', 'IDEALPRO', '1', '0', 'European Monetary Union Euro', '', '', '', '', '', 'US/Eastern', '20241029:1715-20241030:1700;20241030:1715-20241031:1700;20241031:1715-20241101:1700;20241102:CLOSED;20241103:1715-20241104:1700;20241104:1715-20241105:1700', '20241029:1715-20241030:1700;20241030:1715-20241031:1700;20241031:1715-20241101:1700;20241102:CLOSED;20241103:1715-20241104:1700;20241104:1715-20241105:1700', '', '', '0', '4', '', '', '3188', '', '', '0.01', '0.01', '0.01']
Traceback (most recent call last):
  File "c:\Users\felin\AppData\Local\Programs\Python\Python313\Lib\site-packages\ib_insync\decoder.py", line 198, in interpret
    handler(fields)
    ~~~~~~~^^^^^^^^
  File "c:\Users\felin\AppData\Local\Programs\Python\Python313\Lib\site-packages\ib_insync\decoder.py", line 336, in contractDetails
    self.wrapper.contractDetails(int(reqId), cd)
    ~~~~~~~~~~~~~~~~~~~~~~~~~~~~^^^^^^^^^^^^^^^^
  File "c:\Users\felin\AppData\Local\Programs\Python\Python313\Lib\site-packages\ib_insync\wrapper.py", line 537, in contractDetails
    self.ib.contractDetails(reqId, contractDetails)
    ~~~~~~~~~~~~~~~~~~~~~~~^^^^^^^^^^^^^^^^^^^^^^^^
  File "E:\gitcode\backtrader\backtrader\stores\ibstore_insync.py", line 476, in contractDetails
    self.qs[reqId].put(contractDetails)
    ~~~~~~~^^^^^^^
KeyError: 3
2024-10-31 18:09:59.467 - ERROR   - MainThread - decoder.py:189 [handler] - Error for contractDetailsEnd:
Traceback (most recent call last):
  File "c:\Users\felin\AppData\Local\Programs\Python\Python313\Lib\site-packages\ib_insync\decoder.py", line 187, in handler
    method(*args)
    ~~~~~~^^^^^^^
  File "c:\Users\felin\AppData\Local\Programs\Python\Python313\Lib\site-packages\ib_insync\wrapper.py", line 543, in contractDetailsEnd
    self.ib.contractDetailsEnd(reqId)
    ~~~~~~~~~~~~~~~~~~~~~~~~~~^^^^^^^
  File "E:\gitcode\backtrader\backtrader\stores\ibstore_insync.py", line 471, in contractDetailsEnd
    self.cancelQueue(self.qs[reqId], True)
                     ~~~~~~~^^^^^^^
KeyError: 3
